INFO 2024-02-26 14:30:09,985 autoreload autoreload.py 668 run_with_reloader 31164 Watching for file changes with StatReloader
INFO 2024-02-26 14:31:34,063 autoreload autoreload.py 266 trigger_reload 31164 C:\Users\yash.goyal\Desktop\python project\experienced-ai-backend\experience_ai\settings.py changed, reloading.
INFO 2024-02-26 17:52:05,789 autoreload autoreload.py 668 run_with_reloader 56744 Watching for file changes with StatReloader
INFO 2024-02-26 17:52:11,945 autoreload autoreload.py 266 trigger_reload 56744 C:\Users\yash.goyal\Desktop\python project\experienced-ai-backend\authentication\apps.py changed, reloading.
INFO 2024-02-26 17:52:14,994 autoreload autoreload.py 668 run_with_reloader 57016 Watching for file changes with StatReloader
INFO 2024-02-26 17:52:18,610 autoreload autoreload.py 266 trigger_reload 57016 C:\Users\yash.goyal\Desktop\python project\experienced-ai-backend\experience_ai\settings.py changed, reloading.
ERROR 2024-02-27 11:39:15,143 log log.py 241 log_response 85308 Internal Server Error: /apiv1/send-reset-password-email/
Traceback (most recent call last):
  File "C:\Users\yash.goyal\Desktop\python project\experienced-ai-backend\authentication\api\views.py", line 344, in post
    if serializer.is_valid():   # if it doesn't go in if condition it raise an exception
       ^^^^^^^^^^^^^^^^^^^^^
  File "C:\Users\yash.goyal\Desktop\python project\experienced-ai-backend\env\Lib\site-packages\rest_framework\serializers.py", line 227, in is_valid
    self._validated_data = self.run_validation(self.initial_data)
                           ^^^^^^^^^^^^^^^^^^^^^^^^^^^^^^^^^^^^^^
  File "C:\Users\yash.goyal\Desktop\python project\experienced-ai-backend\env\Lib\site-packages\rest_framework\serializers.py", line 429, in run_validation
    value = self.validate(value)
            ^^^^^^^^^^^^^^^^^^^^
  File "C:\Users\yash.goyal\Desktop\python project\experienced-ai-backend\authentication\api\serializers.py", line 160, in validate
    body = render_to_string('authentication/reset_password.html', context)
           ^^^^^^^^^^^^^^^^^^^^^^^^^^^^^^^^^^^^^^^^^^^^^^^^^^^^^^^^^^^^^^^
  File "C:\Users\yash.goyal\Desktop\python project\experienced-ai-backend\env\Lib\site-packages\django\template\loader.py", line 61, in render_to_string
    template = get_template(template_name, using=using)
               ^^^^^^^^^^^^^^^^^^^^^^^^^^^^^^^^^^^^^^^^
  File "C:\Users\yash.goyal\Desktop\python project\experienced-ai-backend\env\Lib\site-packages\django\template\loader.py", line 15, in get_template
    return engine.get_template(template_name)
           ^^^^^^^^^^^^^^^^^^^^^^^^^^^^^^^^^^
  File "C:\Users\yash.goyal\Desktop\python project\experienced-ai-backend\env\Lib\site-packages\django\template\backends\django.py", line 33, in get_template
    return Template(self.engine.get_template(template_name), self)
                    ^^^^^^^^^^^^^^^^^^^^^^^^^^^^^^^^^^^^^^^
  File "C:\Users\yash.goyal\Desktop\python project\experienced-ai-backend\env\Lib\site-packages\django\template\engine.py", line 177, in get_template
    template, origin = self.find_template(template_name)
                       ^^^^^^^^^^^^^^^^^^^^^^^^^^^^^^^^^
  File "C:\Users\yash.goyal\Desktop\python project\experienced-ai-backend\env\Lib\site-packages\django\template\engine.py", line 159, in find_template
    template = loader.get_template(name, skip=skip)
               ^^^^^^^^^^^^^^^^^^^^^^^^^^^^^^^^^^^^
  File "C:\Users\yash.goyal\Desktop\python project\experienced-ai-backend\env\Lib\site-packages\django\template\loaders\cached.py", line 57, in get_template
    template = super().get_template(template_name, skip)
               ^^^^^^^^^^^^^^^^^^^^^^^^^^^^^^^^^^^^^^^^^
  File "C:\Users\yash.goyal\Desktop\python project\experienced-ai-backend\env\Lib\site-packages\django\template\loaders\base.py", line 28, in get_template
    return Template(
           ^^^^^^^^^
  File "C:\Users\yash.goyal\Desktop\python project\experienced-ai-backend\env\Lib\site-packages\django\template\base.py", line 154, in __init__
    self.nodelist = self.compile_nodelist()
                    ^^^^^^^^^^^^^^^^^^^^^^^
  File "C:\Users\yash.goyal\Desktop\python project\experienced-ai-backend\env\Lib\site-packages\django\template\base.py", line 196, in compile_nodelist
    return parser.parse()
           ^^^^^^^^^^^^^^
  File "C:\Users\yash.goyal\Desktop\python project\experienced-ai-backend\env\Lib\site-packages\django\template\base.py", line 481, in parse
    raise self.error(token, e)
  File "C:\Users\yash.goyal\Desktop\python project\experienced-ai-backend\env\Lib\site-packages\django\template\base.py", line 479, in parse
    filter_expression = self.compile_filter(token.contents)
                        ^^^^^^^^^^^^^^^^^^^^^^^^^^^^^^^^^^^
  File "C:\Users\yash.goyal\Desktop\python project\experienced-ai-backend\env\Lib\site-packages\django\template\base.py", line 597, in compile_filter
    return FilterExpression(token, self)
           ^^^^^^^^^^^^^^^^^^^^^^^^^^^^^
  File "C:\Users\yash.goyal\Desktop\python project\experienced-ai-backend\env\Lib\site-packages\django\template\base.py", line 698, in __init__
    raise TemplateSyntaxError(
django.template.exceptions.TemplateSyntaxError: Could not parse the remainder: '://www.acorn-as.com/wp-content/uploads/2020/09/Acorn-Web-Logo.png.webp' from 'https://www.acorn-as.com/wp-content/uploads/2020/09/Acorn-Web-Logo.png.webp'

During handling of the above exception, another exception occurred:

Traceback (most recent call last):
  File "C:\Users\yash.goyal\Desktop\python project\experienced-ai-backend\env\Lib\site-packages\django\core\handlers\exception.py", line 55, in inner
    response = get_response(request)
               ^^^^^^^^^^^^^^^^^^^^^
  File "C:\Users\yash.goyal\Desktop\python project\experienced-ai-backend\env\Lib\site-packages\django\core\handlers\base.py", line 197, in _get_response
    response = wrapped_callback(request, *callback_args, **callback_kwargs)
               ^^^^^^^^^^^^^^^^^^^^^^^^^^^^^^^^^^^^^^^^^^^^^^^^^^^^^^^^^^^^
  File "C:\Users\yash.goyal\Desktop\python project\experienced-ai-backend\env\Lib\site-packages\django\views\decorators\csrf.py", line 65, in _view_wrapper
    return view_func(request, *args, **kwargs)
           ^^^^^^^^^^^^^^^^^^^^^^^^^^^^^^^^^^^
  File "C:\Users\yash.goyal\Desktop\python project\experienced-ai-backend\env\Lib\site-packages\django\views\generic\base.py", line 104, in view
    return self.dispatch(request, *args, **kwargs)
           ^^^^^^^^^^^^^^^^^^^^^^^^^^^^^^^^^^^^^^^
  File "C:\Users\yash.goyal\Desktop\python project\experienced-ai-backend\env\Lib\site-packages\rest_framework\views.py", line 509, in dispatch
    response = self.handle_exception(exc)
               ^^^^^^^^^^^^^^^^^^^^^^^^^^
  File "C:\Users\yash.goyal\Desktop\python project\experienced-ai-backend\env\Lib\site-packages\rest_framework\views.py", line 469, in handle_exception
    self.raise_uncaught_exception(exc)
  File "C:\Users\yash.goyal\Desktop\python project\experienced-ai-backend\env\Lib\site-packages\rest_framework\views.py", line 480, in raise_uncaught_exception
    raise exc
  File "C:\Users\yash.goyal\Desktop\python project\experienced-ai-backend\env\Lib\site-packages\rest_framework\views.py", line 506, in dispatch
    response = handler(request, *args, **kwargs)
               ^^^^^^^^^^^^^^^^^^^^^^^^^^^^^^^^^
  File "C:\Users\yash.goyal\Desktop\python project\experienced-ai-backend\authentication\api\views.py", line 359, in post
    return send_failure_response(message= common["messages"]["SOMETHING_WENT_WRONG"], status=status.HTTP_500_INTERNAL_SERVER_ERROR)
           ^^^^^^^^^^^^^^^^^^^^^^^^^^^^^^^^^^^^^^^^^^^^^^^^^^^^^^^^^^^^^^^^^^^^^^^^^^^^^^^^^^^^^^^^^^^^^^^^^^^^^^^^^^^^^^^^^^^^^^^^
TypeError: send_failure_response() got an unexpected keyword argument 'status'
ERROR 2024-02-27 11:47:59,977 log log.py 241 log_response 85268 Internal Server Error: /apiv1/send-reset-password-email/
Traceback (most recent call last):
  File "C:\Users\yash.goyal\Desktop\python project\experienced-ai-backend\env\Lib\site-packages\django\template\base.py", line 502, in parse
    compile_func = self.tags[command]
                   ~~~~~~~~~^^^^^^^^^
KeyError: 'static'

During handling of the above exception, another exception occurred:

Traceback (most recent call last):
  File "C:\Users\yash.goyal\Desktop\python project\experienced-ai-backend\authentication\api\views.py", line 344, in post
    if serializer.is_valid():   # if it doesn't go in if condition it raise an exception
       ^^^^^^^^^^^^^^^^^^^^^
  File "C:\Users\yash.goyal\Desktop\python project\experienced-ai-backend\env\Lib\site-packages\rest_framework\serializers.py", line 227, in is_valid
    self._validated_data = self.run_validation(self.initial_data)
                           ^^^^^^^^^^^^^^^^^^^^^^^^^^^^^^^^^^^^^^
  File "C:\Users\yash.goyal\Desktop\python project\experienced-ai-backend\env\Lib\site-packages\rest_framework\serializers.py", line 429, in run_validation
    value = self.validate(value)
            ^^^^^^^^^^^^^^^^^^^^
  File "C:\Users\yash.goyal\Desktop\python project\experienced-ai-backend\authentication\api\serializers.py", line 161, in validate
    body = render_to_string('authentication/reset_password.html', context)
           ^^^^^^^^^^^^^^^^^^^^^^^^^^^^^^^^^^^^^^^^^^^^^^^^^^^^^^^^^^^^^^^
  File "C:\Users\yash.goyal\Desktop\python project\experienced-ai-backend\env\Lib\site-packages\django\template\loader.py", line 61, in render_to_string
    template = get_template(template_name, using=using)
               ^^^^^^^^^^^^^^^^^^^^^^^^^^^^^^^^^^^^^^^^
  File "C:\Users\yash.goyal\Desktop\python project\experienced-ai-backend\env\Lib\site-packages\django\template\loader.py", line 15, in get_template
    return engine.get_template(template_name)
           ^^^^^^^^^^^^^^^^^^^^^^^^^^^^^^^^^^
  File "C:\Users\yash.goyal\Desktop\python project\experienced-ai-backend\env\Lib\site-packages\django\template\backends\django.py", line 33, in get_template
    return Template(self.engine.get_template(template_name), self)
                    ^^^^^^^^^^^^^^^^^^^^^^^^^^^^^^^^^^^^^^^
  File "C:\Users\yash.goyal\Desktop\python project\experienced-ai-backend\env\Lib\site-packages\django\template\engine.py", line 177, in get_template
    template, origin = self.find_template(template_name)
                       ^^^^^^^^^^^^^^^^^^^^^^^^^^^^^^^^^
  File "C:\Users\yash.goyal\Desktop\python project\experienced-ai-backend\env\Lib\site-packages\django\template\engine.py", line 159, in find_template
    template = loader.get_template(name, skip=skip)
               ^^^^^^^^^^^^^^^^^^^^^^^^^^^^^^^^^^^^
  File "C:\Users\yash.goyal\Desktop\python project\experienced-ai-backend\env\Lib\site-packages\django\template\loaders\cached.py", line 57, in get_template
    template = super().get_template(template_name, skip)
               ^^^^^^^^^^^^^^^^^^^^^^^^^^^^^^^^^^^^^^^^^
  File "C:\Users\yash.goyal\Desktop\python project\experienced-ai-backend\env\Lib\site-packages\django\template\loaders\base.py", line 28, in get_template
    return Template(
           ^^^^^^^^^
  File "C:\Users\yash.goyal\Desktop\python project\experienced-ai-backend\env\Lib\site-packages\django\template\base.py", line 154, in __init__
    self.nodelist = self.compile_nodelist()
                    ^^^^^^^^^^^^^^^^^^^^^^^
  File "C:\Users\yash.goyal\Desktop\python project\experienced-ai-backend\env\Lib\site-packages\django\template\base.py", line 196, in compile_nodelist
    return parser.parse()
           ^^^^^^^^^^^^^^
  File "C:\Users\yash.goyal\Desktop\python project\experienced-ai-backend\env\Lib\site-packages\django\template\base.py", line 504, in parse
    self.invalid_block_tag(token, command, parse_until)
  File "C:\Users\yash.goyal\Desktop\python project\experienced-ai-backend\env\Lib\site-packages\django\template\base.py", line 565, in invalid_block_tag
    raise self.error(
django.template.exceptions.TemplateSyntaxError: Invalid block tag on line 13: 'static'. Did you forget to register or load this tag?

During handling of the above exception, another exception occurred:

Traceback (most recent call last):
  File "C:\Users\yash.goyal\Desktop\python project\experienced-ai-backend\env\Lib\site-packages\django\core\handlers\exception.py", line 55, in inner
    response = get_response(request)
               ^^^^^^^^^^^^^^^^^^^^^
  File "C:\Users\yash.goyal\Desktop\python project\experienced-ai-backend\env\Lib\site-packages\django\core\handlers\base.py", line 197, in _get_response
    response = wrapped_callback(request, *callback_args, **callback_kwargs)
               ^^^^^^^^^^^^^^^^^^^^^^^^^^^^^^^^^^^^^^^^^^^^^^^^^^^^^^^^^^^^
  File "C:\Users\yash.goyal\Desktop\python project\experienced-ai-backend\env\Lib\site-packages\django\views\decorators\csrf.py", line 65, in _view_wrapper
    return view_func(request, *args, **kwargs)
           ^^^^^^^^^^^^^^^^^^^^^^^^^^^^^^^^^^^
  File "C:\Users\yash.goyal\Desktop\python project\experienced-ai-backend\env\Lib\site-packages\django\views\generic\base.py", line 104, in view
    return self.dispatch(request, *args, **kwargs)
           ^^^^^^^^^^^^^^^^^^^^^^^^^^^^^^^^^^^^^^^
  File "C:\Users\yash.goyal\Desktop\python project\experienced-ai-backend\env\Lib\site-packages\rest_framework\views.py", line 509, in dispatch
    response = self.handle_exception(exc)
               ^^^^^^^^^^^^^^^^^^^^^^^^^^
  File "C:\Users\yash.goyal\Desktop\python project\experienced-ai-backend\env\Lib\site-packages\rest_framework\views.py", line 469, in handle_exception
    self.raise_uncaught_exception(exc)
  File "C:\Users\yash.goyal\Desktop\python project\experienced-ai-backend\env\Lib\site-packages\rest_framework\views.py", line 480, in raise_uncaught_exception
    raise exc
  File "C:\Users\yash.goyal\Desktop\python project\experienced-ai-backend\env\Lib\site-packages\rest_framework\views.py", line 506, in dispatch
    response = handler(request, *args, **kwargs)
               ^^^^^^^^^^^^^^^^^^^^^^^^^^^^^^^^^
  File "C:\Users\yash.goyal\Desktop\python project\experienced-ai-backend\authentication\api\views.py", line 359, in post
    return send_failure_response(message= common["messages"]["SOMETHING_WENT_WRONG"], status=status.HTTP_500_INTERNAL_SERVER_ERROR)
           ^^^^^^^^^^^^^^^^^^^^^^^^^^^^^^^^^^^^^^^^^^^^^^^^^^^^^^^^^^^^^^^^^^^^^^^^^^^^^^^^^^^^^^^^^^^^^^^^^^^^^^^^^^^^^^^^^^^^^^^^
TypeError: send_failure_response() got an unexpected keyword argument 'status'
ERROR 2024-02-27 11:51:44,859 log log.py 241 log_response 81884 Internal Server Error: /apiv1/send-reset-password-email/
ERROR 2024-02-27 11:52:50,958 log log.py 241 log_response 88120 Internal Server Error: /apiv1/send-reset-password-email/
ERROR 2024-02-27 12:03:43,981 log log.py 241 log_response 89280 Internal Server Error: /apiv1/send-reset-password-email/
ERROR 2024-02-27 12:04:13,749 log log.py 241 log_response 87624 Internal Server Error: /apiv1/send-reset-password-email/
ERROR 2024-02-27 12:06:53,400 log log.py 241 log_response 87624 Internal Server Error: /apiv1/send-reset-password-email/
ERROR 2024-02-27 12:44:46,578 log log.py 241 log_response 95052 Internal Server Error: /apiv1/send-reset-password-email/
ERROR 2024-02-27 12:55:20,008 log log.py 241 log_response 96496 Internal Server Error: /apiv1/send-reset-password-email/
ERROR 2024-02-27 12:59:00,749 log log.py 241 log_response 97060 Internal Server Error: /apiv1/send-reset-password-email/
ERROR 2024-02-27 12:59:18,249 log log.py 241 log_response 97060 Internal Server Error: /apiv1/send-reset-password-email/
ERROR 2024-02-27 15:16:53,543 log log.py 241 log_response 109164 Internal Server Error: /apiv1/logout/
Traceback (most recent call last):
  File "C:\Users\yash.goyal\Desktop\python project\experienced-ai-backend\authentication\api\views.py", line 639, in post
    token = Token.objects.get(user=request.user)
            ^^^^^^^^^^^^^
AttributeError: type object 'Token' has no attribute 'objects'

During handling of the above exception, another exception occurred:

Traceback (most recent call last):
  File "C:\Users\yash.goyal\Desktop\python project\experienced-ai-backend\env\Lib\site-packages\django\core\handlers\exception.py", line 55, in inner
    response = get_response(request)
               ^^^^^^^^^^^^^^^^^^^^^
  File "C:\Users\yash.goyal\Desktop\python project\experienced-ai-backend\env\Lib\site-packages\django\core\handlers\base.py", line 197, in _get_response
    response = wrapped_callback(request, *callback_args, **callback_kwargs)
               ^^^^^^^^^^^^^^^^^^^^^^^^^^^^^^^^^^^^^^^^^^^^^^^^^^^^^^^^^^^^
  File "C:\Users\yash.goyal\Desktop\python project\experienced-ai-backend\env\Lib\site-packages\django\views\decorators\csrf.py", line 65, in _view_wrapper
    return view_func(request, *args, **kwargs)
           ^^^^^^^^^^^^^^^^^^^^^^^^^^^^^^^^^^^
  File "C:\Users\yash.goyal\Desktop\python project\experienced-ai-backend\env\Lib\site-packages\django\views\generic\base.py", line 104, in view
    return self.dispatch(request, *args, **kwargs)
           ^^^^^^^^^^^^^^^^^^^^^^^^^^^^^^^^^^^^^^^
  File "C:\Users\yash.goyal\Desktop\python project\experienced-ai-backend\env\Lib\site-packages\rest_framework\views.py", line 509, in dispatch
    response = self.handle_exception(exc)
               ^^^^^^^^^^^^^^^^^^^^^^^^^^
  File "C:\Users\yash.goyal\Desktop\python project\experienced-ai-backend\env\Lib\site-packages\rest_framework\views.py", line 469, in handle_exception
    self.raise_uncaught_exception(exc)
  File "C:\Users\yash.goyal\Desktop\python project\experienced-ai-backend\env\Lib\site-packages\rest_framework\views.py", line 480, in raise_uncaught_exception
    raise exc
  File "C:\Users\yash.goyal\Desktop\python project\experienced-ai-backend\env\Lib\site-packages\rest_framework\views.py", line 506, in dispatch
    response = handler(request, *args, **kwargs)
               ^^^^^^^^^^^^^^^^^^^^^^^^^^^^^^^^^
  File "C:\Users\yash.goyal\Desktop\python project\experienced-ai-backend\authentication\api\views.py", line 643, in post
    except Token.DoesNotExist:
           ^^^^^^^^^^^^^^^^^^
AttributeError: type object 'Token' has no attribute 'DoesNotExist'
ERROR 2024-02-27 15:18:06,018 log log.py 241 log_response 108368 Internal Server Error: /apiv1/logout/
Traceback (most recent call last):
  File "C:\Users\yash.goyal\Desktop\python project\experienced-ai-backend\env\Lib\site-packages\django\core\handlers\exception.py", line 55, in inner
    response = get_response(request)
               ^^^^^^^^^^^^^^^^^^^^^
  File "C:\Users\yash.goyal\Desktop\python project\experienced-ai-backend\env\Lib\site-packages\django\core\handlers\base.py", line 197, in _get_response
    response = wrapped_callback(request, *callback_args, **callback_kwargs)
               ^^^^^^^^^^^^^^^^^^^^^^^^^^^^^^^^^^^^^^^^^^^^^^^^^^^^^^^^^^^^
  File "C:\Users\yash.goyal\Desktop\python project\experienced-ai-backend\env\Lib\site-packages\django\views\decorators\csrf.py", line 65, in _view_wrapper
    return view_func(request, *args, **kwargs)
           ^^^^^^^^^^^^^^^^^^^^^^^^^^^^^^^^^^^
  File "C:\Users\yash.goyal\Desktop\python project\experienced-ai-backend\env\Lib\site-packages\django\views\generic\base.py", line 104, in view
    return self.dispatch(request, *args, **kwargs)
           ^^^^^^^^^^^^^^^^^^^^^^^^^^^^^^^^^^^^^^^
  File "C:\Users\yash.goyal\Desktop\python project\experienced-ai-backend\env\Lib\site-packages\rest_framework\views.py", line 509, in dispatch
    response = self.handle_exception(exc)
               ^^^^^^^^^^^^^^^^^^^^^^^^^^
  File "C:\Users\yash.goyal\Desktop\python project\experienced-ai-backend\env\Lib\site-packages\rest_framework\views.py", line 469, in handle_exception
    self.raise_uncaught_exception(exc)
  File "C:\Users\yash.goyal\Desktop\python project\experienced-ai-backend\env\Lib\site-packages\rest_framework\views.py", line 480, in raise_uncaught_exception
    raise exc
  File "C:\Users\yash.goyal\Desktop\python project\experienced-ai-backend\env\Lib\site-packages\rest_framework\views.py", line 506, in dispatch
    response = handler(request, *args, **kwargs)
               ^^^^^^^^^^^^^^^^^^^^^^^^^^^^^^^^^
  File "C:\Users\yash.goyal\Desktop\python project\experienced-ai-backend\authentication\api\views.py", line 640, in post
    token = Token.objects.get(user=request.user)
            ^^^^^^^^^^^^^
AttributeError: type object 'Token' has no attribute 'objects'
ERROR 2024-02-27 15:19:32,329 log log.py 241 log_response 108860 Internal Server Error: /apiv1/logout/
Traceback (most recent call last):
  File "C:\Users\yash.goyal\Desktop\python project\experienced-ai-backend\authentication\api\views.py", line 640, in post
    token = Token.objects.get(user=request.user)
            ^^^^^^^^^^^^^
AttributeError: type object 'Token' has no attribute 'objects'

During handling of the above exception, another exception occurred:

Traceback (most recent call last):
  File "C:\Users\yash.goyal\Desktop\python project\experienced-ai-backend\env\Lib\site-packages\django\core\handlers\exception.py", line 55, in inner
    response = get_response(request)
               ^^^^^^^^^^^^^^^^^^^^^
  File "C:\Users\yash.goyal\Desktop\python project\experienced-ai-backend\env\Lib\site-packages\django\core\handlers\base.py", line 197, in _get_response
    response = wrapped_callback(request, *callback_args, **callback_kwargs)
               ^^^^^^^^^^^^^^^^^^^^^^^^^^^^^^^^^^^^^^^^^^^^^^^^^^^^^^^^^^^^
  File "C:\Users\yash.goyal\Desktop\python project\experienced-ai-backend\env\Lib\site-packages\django\views\decorators\csrf.py", line 65, in _view_wrapper
    return view_func(request, *args, **kwargs)
           ^^^^^^^^^^^^^^^^^^^^^^^^^^^^^^^^^^^
  File "C:\Users\yash.goyal\Desktop\python project\experienced-ai-backend\env\Lib\site-packages\django\views\generic\base.py", line 104, in view
    return self.dispatch(request, *args, **kwargs)
           ^^^^^^^^^^^^^^^^^^^^^^^^^^^^^^^^^^^^^^^
  File "C:\Users\yash.goyal\Desktop\python project\experienced-ai-backend\env\Lib\site-packages\rest_framework\views.py", line 509, in dispatch
    response = self.handle_exception(exc)
               ^^^^^^^^^^^^^^^^^^^^^^^^^^
  File "C:\Users\yash.goyal\Desktop\python project\experienced-ai-backend\env\Lib\site-packages\rest_framework\views.py", line 469, in handle_exception
    self.raise_uncaught_exception(exc)
  File "C:\Users\yash.goyal\Desktop\python project\experienced-ai-backend\env\Lib\site-packages\rest_framework\views.py", line 480, in raise_uncaught_exception
    raise exc
  File "C:\Users\yash.goyal\Desktop\python project\experienced-ai-backend\env\Lib\site-packages\rest_framework\views.py", line 506, in dispatch
    response = handler(request, *args, **kwargs)
               ^^^^^^^^^^^^^^^^^^^^^^^^^^^^^^^^^
  File "C:\Users\yash.goyal\Desktop\python project\experienced-ai-backend\authentication\api\views.py", line 644, in post
    except Token.DoesNotExist:
           ^^^^^^^^^^^^^^^^^^
AttributeError: type object 'Token' has no attribute 'DoesNotExist'
ERROR 2024-02-27 15:20:26,801 log log.py 241 log_response 110544 Internal Server Error: /apiv1/logout/
Traceback (most recent call last):
  File "C:\Users\yash.goyal\Desktop\python project\experienced-ai-backend\authentication\api\views.py", line 640, in post
    token = Token.objects.get(user=request.user)
            ^^^^^^^^^^^^^
AttributeError: type object 'Token' has no attribute 'objects'

During handling of the above exception, another exception occurred:

Traceback (most recent call last):
  File "C:\Users\yash.goyal\Desktop\python project\experienced-ai-backend\env\Lib\site-packages\django\core\handlers\exception.py", line 55, in inner
    response = get_response(request)
               ^^^^^^^^^^^^^^^^^^^^^
  File "C:\Users\yash.goyal\Desktop\python project\experienced-ai-backend\env\Lib\site-packages\django\core\handlers\base.py", line 197, in _get_response
    response = wrapped_callback(request, *callback_args, **callback_kwargs)
               ^^^^^^^^^^^^^^^^^^^^^^^^^^^^^^^^^^^^^^^^^^^^^^^^^^^^^^^^^^^^
  File "C:\Users\yash.goyal\Desktop\python project\experienced-ai-backend\env\Lib\site-packages\django\views\decorators\csrf.py", line 65, in _view_wrapper
    return view_func(request, *args, **kwargs)
           ^^^^^^^^^^^^^^^^^^^^^^^^^^^^^^^^^^^
  File "C:\Users\yash.goyal\Desktop\python project\experienced-ai-backend\env\Lib\site-packages\django\views\generic\base.py", line 104, in view
    return self.dispatch(request, *args, **kwargs)
           ^^^^^^^^^^^^^^^^^^^^^^^^^^^^^^^^^^^^^^^
  File "C:\Users\yash.goyal\Desktop\python project\experienced-ai-backend\env\Lib\site-packages\rest_framework\views.py", line 509, in dispatch
    response = self.handle_exception(exc)
               ^^^^^^^^^^^^^^^^^^^^^^^^^^
  File "C:\Users\yash.goyal\Desktop\python project\experienced-ai-backend\env\Lib\site-packages\rest_framework\views.py", line 469, in handle_exception
    self.raise_uncaught_exception(exc)
  File "C:\Users\yash.goyal\Desktop\python project\experienced-ai-backend\env\Lib\site-packages\rest_framework\views.py", line 480, in raise_uncaught_exception
    raise exc
  File "C:\Users\yash.goyal\Desktop\python project\experienced-ai-backend\env\Lib\site-packages\rest_framework\views.py", line 506, in dispatch
    response = handler(request, *args, **kwargs)
               ^^^^^^^^^^^^^^^^^^^^^^^^^^^^^^^^^
  File "C:\Users\yash.goyal\Desktop\python project\experienced-ai-backend\authentication\api\views.py", line 644, in post
    except Token.DoesNotExist:
           ^^^^^^^^^^^^^^^^^^
AttributeError: type object 'Token' has no attribute 'DoesNotExist'
ERROR 2024-02-27 15:21:09,033 log log.py 241 log_response 109624 Internal Server Error: /apiv1/logout/
Traceback (most recent call last):
  File "C:\Users\yash.goyal\Desktop\python project\experienced-ai-backend\authentication\api\views.py", line 644, in post
    token = Token.objects.get(user=request.user)
            ^^^^^^^^^^^^^
AttributeError: type object 'Token' has no attribute 'objects'

During handling of the above exception, another exception occurred:

Traceback (most recent call last):
  File "C:\Users\yash.goyal\Desktop\python project\experienced-ai-backend\env\Lib\site-packages\django\core\handlers\exception.py", line 55, in inner
    response = get_response(request)
               ^^^^^^^^^^^^^^^^^^^^^
  File "C:\Users\yash.goyal\Desktop\python project\experienced-ai-backend\env\Lib\site-packages\django\core\handlers\base.py", line 197, in _get_response
    response = wrapped_callback(request, *callback_args, **callback_kwargs)
               ^^^^^^^^^^^^^^^^^^^^^^^^^^^^^^^^^^^^^^^^^^^^^^^^^^^^^^^^^^^^
  File "C:\Users\yash.goyal\Desktop\python project\experienced-ai-backend\env\Lib\site-packages\django\views\decorators\csrf.py", line 65, in _view_wrapper
    return view_func(request, *args, **kwargs)
           ^^^^^^^^^^^^^^^^^^^^^^^^^^^^^^^^^^^
  File "C:\Users\yash.goyal\Desktop\python project\experienced-ai-backend\env\Lib\site-packages\django\views\generic\base.py", line 104, in view
    return self.dispatch(request, *args, **kwargs)
           ^^^^^^^^^^^^^^^^^^^^^^^^^^^^^^^^^^^^^^^
  File "C:\Users\yash.goyal\Desktop\python project\experienced-ai-backend\env\Lib\site-packages\rest_framework\views.py", line 509, in dispatch
    response = self.handle_exception(exc)
               ^^^^^^^^^^^^^^^^^^^^^^^^^^
  File "C:\Users\yash.goyal\Desktop\python project\experienced-ai-backend\env\Lib\site-packages\rest_framework\views.py", line 469, in handle_exception
    self.raise_uncaught_exception(exc)
  File "C:\Users\yash.goyal\Desktop\python project\experienced-ai-backend\env\Lib\site-packages\rest_framework\views.py", line 480, in raise_uncaught_exception
    raise exc
  File "C:\Users\yash.goyal\Desktop\python project\experienced-ai-backend\env\Lib\site-packages\rest_framework\views.py", line 506, in dispatch
    response = handler(request, *args, **kwargs)
               ^^^^^^^^^^^^^^^^^^^^^^^^^^^^^^^^^
  File "C:\Users\yash.goyal\Desktop\python project\experienced-ai-backend\authentication\api\views.py", line 648, in post
    except Token.DoesNotExist:
           ^^^^^^^^^^^^^^^^^^
AttributeError: type object 'Token' has no attribute 'DoesNotExist'
ERROR 2024-02-27 15:21:11,467 log log.py 241 log_response 109624 Internal Server Error: /apiv1/logout/
Traceback (most recent call last):
  File "C:\Users\yash.goyal\Desktop\python project\experienced-ai-backend\authentication\api\views.py", line 644, in post
    token = Token.objects.get(user=request.user)
            ^^^^^^^^^^^^^
AttributeError: type object 'Token' has no attribute 'objects'

During handling of the above exception, another exception occurred:

Traceback (most recent call last):
  File "C:\Users\yash.goyal\Desktop\python project\experienced-ai-backend\env\Lib\site-packages\django\core\handlers\exception.py", line 55, in inner
    response = get_response(request)
               ^^^^^^^^^^^^^^^^^^^^^
  File "C:\Users\yash.goyal\Desktop\python project\experienced-ai-backend\env\Lib\site-packages\django\core\handlers\base.py", line 197, in _get_response
    response = wrapped_callback(request, *callback_args, **callback_kwargs)
               ^^^^^^^^^^^^^^^^^^^^^^^^^^^^^^^^^^^^^^^^^^^^^^^^^^^^^^^^^^^^
  File "C:\Users\yash.goyal\Desktop\python project\experienced-ai-backend\env\Lib\site-packages\django\views\decorators\csrf.py", line 65, in _view_wrapper
    return view_func(request, *args, **kwargs)
           ^^^^^^^^^^^^^^^^^^^^^^^^^^^^^^^^^^^
  File "C:\Users\yash.goyal\Desktop\python project\experienced-ai-backend\env\Lib\site-packages\django\views\generic\base.py", line 104, in view
    return self.dispatch(request, *args, **kwargs)
           ^^^^^^^^^^^^^^^^^^^^^^^^^^^^^^^^^^^^^^^
  File "C:\Users\yash.goyal\Desktop\python project\experienced-ai-backend\env\Lib\site-packages\rest_framework\views.py", line 509, in dispatch
    response = self.handle_exception(exc)
               ^^^^^^^^^^^^^^^^^^^^^^^^^^
  File "C:\Users\yash.goyal\Desktop\python project\experienced-ai-backend\env\Lib\site-packages\rest_framework\views.py", line 469, in handle_exception
    self.raise_uncaught_exception(exc)
  File "C:\Users\yash.goyal\Desktop\python project\experienced-ai-backend\env\Lib\site-packages\rest_framework\views.py", line 480, in raise_uncaught_exception
    raise exc
  File "C:\Users\yash.goyal\Desktop\python project\experienced-ai-backend\env\Lib\site-packages\rest_framework\views.py", line 506, in dispatch
    response = handler(request, *args, **kwargs)
               ^^^^^^^^^^^^^^^^^^^^^^^^^^^^^^^^^
  File "C:\Users\yash.goyal\Desktop\python project\experienced-ai-backend\authentication\api\views.py", line 648, in post
    except Token.DoesNotExist:
           ^^^^^^^^^^^^^^^^^^
AttributeError: type object 'Token' has no attribute 'DoesNotExist'
ERROR 2024-02-27 15:21:33,286 log log.py 241 log_response 108344 Internal Server Error: /apiv1/logout/
Traceback (most recent call last):
  File "C:\Users\yash.goyal\Desktop\python project\experienced-ai-backend\authentication\api\views.py", line 644, in post
    token = Token.objects.get(user=request.user)
            ^^^^^^^^^^^^^
AttributeError: type object 'Token' has no attribute 'objects'

During handling of the above exception, another exception occurred:

Traceback (most recent call last):
  File "C:\Users\yash.goyal\Desktop\python project\experienced-ai-backend\env\Lib\site-packages\django\core\handlers\exception.py", line 55, in inner
    response = get_response(request)
               ^^^^^^^^^^^^^^^^^^^^^
  File "C:\Users\yash.goyal\Desktop\python project\experienced-ai-backend\env\Lib\site-packages\django\core\handlers\base.py", line 197, in _get_response
    response = wrapped_callback(request, *callback_args, **callback_kwargs)
               ^^^^^^^^^^^^^^^^^^^^^^^^^^^^^^^^^^^^^^^^^^^^^^^^^^^^^^^^^^^^
  File "C:\Users\yash.goyal\Desktop\python project\experienced-ai-backend\env\Lib\site-packages\django\views\decorators\csrf.py", line 65, in _view_wrapper
    return view_func(request, *args, **kwargs)
           ^^^^^^^^^^^^^^^^^^^^^^^^^^^^^^^^^^^
  File "C:\Users\yash.goyal\Desktop\python project\experienced-ai-backend\env\Lib\site-packages\django\views\generic\base.py", line 104, in view
    return self.dispatch(request, *args, **kwargs)
           ^^^^^^^^^^^^^^^^^^^^^^^^^^^^^^^^^^^^^^^
  File "C:\Users\yash.goyal\Desktop\python project\experienced-ai-backend\env\Lib\site-packages\rest_framework\views.py", line 509, in dispatch
    response = self.handle_exception(exc)
               ^^^^^^^^^^^^^^^^^^^^^^^^^^
  File "C:\Users\yash.goyal\Desktop\python project\experienced-ai-backend\env\Lib\site-packages\rest_framework\views.py", line 469, in handle_exception
    self.raise_uncaught_exception(exc)
  File "C:\Users\yash.goyal\Desktop\python project\experienced-ai-backend\env\Lib\site-packages\rest_framework\views.py", line 480, in raise_uncaught_exception
    raise exc
  File "C:\Users\yash.goyal\Desktop\python project\experienced-ai-backend\env\Lib\site-packages\rest_framework\views.py", line 506, in dispatch
    response = handler(request, *args, **kwargs)
               ^^^^^^^^^^^^^^^^^^^^^^^^^^^^^^^^^
  File "C:\Users\yash.goyal\Desktop\python project\experienced-ai-backend\authentication\api\views.py", line 648, in post
    except Token.DoesNotExist:
           ^^^^^^^^^^^^^^^^^^
AttributeError: type object 'Token' has no attribute 'DoesNotExist'
ERROR 2024-02-27 15:28:02,971 log log.py 241 log_response 110512 Internal Server Error: /apiv1/logout/
Traceback (most recent call last):
  File "C:\Users\yash.goyal\Desktop\python project\experienced-ai-backend\authentication\api\views.py", line 645, in post
    token = Token.objects.get(user=request.user)
            ^^^^^^^^^^^^^
AttributeError: type object 'Token' has no attribute 'objects'

During handling of the above exception, another exception occurred:

Traceback (most recent call last):
  File "C:\Users\yash.goyal\Desktop\python project\experienced-ai-backend\env\Lib\site-packages\django\core\handlers\exception.py", line 55, in inner
    response = get_response(request)
               ^^^^^^^^^^^^^^^^^^^^^
  File "C:\Users\yash.goyal\Desktop\python project\experienced-ai-backend\env\Lib\site-packages\django\core\handlers\base.py", line 197, in _get_response
    response = wrapped_callback(request, *callback_args, **callback_kwargs)
               ^^^^^^^^^^^^^^^^^^^^^^^^^^^^^^^^^^^^^^^^^^^^^^^^^^^^^^^^^^^^
  File "C:\Users\yash.goyal\Desktop\python project\experienced-ai-backend\env\Lib\site-packages\django\views\decorators\csrf.py", line 65, in _view_wrapper
    return view_func(request, *args, **kwargs)
           ^^^^^^^^^^^^^^^^^^^^^^^^^^^^^^^^^^^
  File "C:\Users\yash.goyal\Desktop\python project\experienced-ai-backend\env\Lib\site-packages\django\views\generic\base.py", line 104, in view
    return self.dispatch(request, *args, **kwargs)
           ^^^^^^^^^^^^^^^^^^^^^^^^^^^^^^^^^^^^^^^
  File "C:\Users\yash.goyal\Desktop\python project\experienced-ai-backend\env\Lib\site-packages\rest_framework\views.py", line 509, in dispatch
    response = self.handle_exception(exc)
               ^^^^^^^^^^^^^^^^^^^^^^^^^^
  File "C:\Users\yash.goyal\Desktop\python project\experienced-ai-backend\env\Lib\site-packages\rest_framework\views.py", line 469, in handle_exception
    self.raise_uncaught_exception(exc)
  File "C:\Users\yash.goyal\Desktop\python project\experienced-ai-backend\env\Lib\site-packages\rest_framework\views.py", line 480, in raise_uncaught_exception
    raise exc
  File "C:\Users\yash.goyal\Desktop\python project\experienced-ai-backend\env\Lib\site-packages\rest_framework\views.py", line 506, in dispatch
    response = handler(request, *args, **kwargs)
               ^^^^^^^^^^^^^^^^^^^^^^^^^^^^^^^^^
  File "C:\Users\yash.goyal\Desktop\python project\experienced-ai-backend\authentication\api\views.py", line 649, in post
    except Token.ObjectDoesNotExist:
           ^^^^^^^^^^^^^^^^^^^^^^^^
AttributeError: type object 'Token' has no attribute 'ObjectDoesNotExist'
ERROR 2024-02-27 15:28:31,705 log log.py 241 log_response 107936 Internal Server Error: /apiv1/logout/
Traceback (most recent call last):
  File "C:\Users\yash.goyal\Desktop\python project\experienced-ai-backend\env\Lib\site-packages\django\core\handlers\exception.py", line 55, in inner
    response = get_response(request)
               ^^^^^^^^^^^^^^^^^^^^^
  File "C:\Users\yash.goyal\Desktop\python project\experienced-ai-backend\env\Lib\site-packages\django\core\handlers\base.py", line 197, in _get_response
    response = wrapped_callback(request, *callback_args, **callback_kwargs)
               ^^^^^^^^^^^^^^^^^^^^^^^^^^^^^^^^^^^^^^^^^^^^^^^^^^^^^^^^^^^^
  File "C:\Users\yash.goyal\Desktop\python project\experienced-ai-backend\env\Lib\site-packages\django\views\decorators\csrf.py", line 65, in _view_wrapper
    return view_func(request, *args, **kwargs)
           ^^^^^^^^^^^^^^^^^^^^^^^^^^^^^^^^^^^
  File "C:\Users\yash.goyal\Desktop\python project\experienced-ai-backend\env\Lib\site-packages\django\views\generic\base.py", line 104, in view
    return self.dispatch(request, *args, **kwargs)
           ^^^^^^^^^^^^^^^^^^^^^^^^^^^^^^^^^^^^^^^
  File "C:\Users\yash.goyal\Desktop\python project\experienced-ai-backend\env\Lib\site-packages\rest_framework\views.py", line 509, in dispatch
    response = self.handle_exception(exc)
               ^^^^^^^^^^^^^^^^^^^^^^^^^^
  File "C:\Users\yash.goyal\Desktop\python project\experienced-ai-backend\env\Lib\site-packages\rest_framework\views.py", line 469, in handle_exception
    self.raise_uncaught_exception(exc)
  File "C:\Users\yash.goyal\Desktop\python project\experienced-ai-backend\env\Lib\site-packages\rest_framework\views.py", line 480, in raise_uncaught_exception
    raise exc
  File "C:\Users\yash.goyal\Desktop\python project\experienced-ai-backend\env\Lib\site-packages\rest_framework\views.py", line 506, in dispatch
    response = handler(request, *args, **kwargs)
               ^^^^^^^^^^^^^^^^^^^^^^^^^^^^^^^^^
  File "C:\Users\yash.goyal\Desktop\python project\experienced-ai-backend\authentication\api\views.py", line 645, in post
    token = Token.objects.get(user=request.user)
            ^^^^^^^^^^^^^
AttributeError: type object 'Token' has no attribute 'objects'
ERROR 2024-02-27 15:29:41,501 log log.py 241 log_response 111600 Internal Server Error: /apiv1/logout/
Traceback (most recent call last):
  File "C:\Users\yash.goyal\Desktop\python project\experienced-ai-backend\env\Lib\site-packages\django\core\handlers\exception.py", line 55, in inner
    response = get_response(request)
               ^^^^^^^^^^^^^^^^^^^^^
  File "C:\Users\yash.goyal\Desktop\python project\experienced-ai-backend\env\Lib\site-packages\django\core\handlers\base.py", line 197, in _get_response
    response = wrapped_callback(request, *callback_args, **callback_kwargs)
               ^^^^^^^^^^^^^^^^^^^^^^^^^^^^^^^^^^^^^^^^^^^^^^^^^^^^^^^^^^^^
  File "C:\Users\yash.goyal\Desktop\python project\experienced-ai-backend\env\Lib\site-packages\django\views\decorators\csrf.py", line 65, in _view_wrapper
    return view_func(request, *args, **kwargs)
           ^^^^^^^^^^^^^^^^^^^^^^^^^^^^^^^^^^^
  File "C:\Users\yash.goyal\Desktop\python project\experienced-ai-backend\env\Lib\site-packages\django\views\generic\base.py", line 104, in view
    return self.dispatch(request, *args, **kwargs)
           ^^^^^^^^^^^^^^^^^^^^^^^^^^^^^^^^^^^^^^^
  File "C:\Users\yash.goyal\Desktop\python project\experienced-ai-backend\env\Lib\site-packages\rest_framework\views.py", line 509, in dispatch
    response = self.handle_exception(exc)
               ^^^^^^^^^^^^^^^^^^^^^^^^^^
  File "C:\Users\yash.goyal\Desktop\python project\experienced-ai-backend\env\Lib\site-packages\rest_framework\views.py", line 469, in handle_exception
    self.raise_uncaught_exception(exc)
  File "C:\Users\yash.goyal\Desktop\python project\experienced-ai-backend\env\Lib\site-packages\rest_framework\views.py", line 480, in raise_uncaught_exception
    raise exc
  File "C:\Users\yash.goyal\Desktop\python project\experienced-ai-backend\env\Lib\site-packages\rest_framework\views.py", line 506, in dispatch
    response = handler(request, *args, **kwargs)
               ^^^^^^^^^^^^^^^^^^^^^^^^^^^^^^^^^
  File "C:\Users\yash.goyal\Desktop\python project\experienced-ai-backend\authentication\api\views.py", line 644, in post
    token = Token.objects.filter(user=request.user).first()
            ^^^^^^^^^^^^^
AttributeError: type object 'Token' has no attribute 'objects'
ERROR 2024-02-27 15:31:19,129 log log.py 241 log_response 107552 Internal Server Error: /apiv1/logout/
Traceback (most recent call last):
  File "C:\Users\yash.goyal\Desktop\python project\experienced-ai-backend\authentication\api\views.py", line 644, in post
    token = Token.objects.get(user=request.user)
            ^^^^^^^^^^^^^
AttributeError: type object 'Token' has no attribute 'objects'

During handling of the above exception, another exception occurred:

Traceback (most recent call last):
  File "C:\Users\yash.goyal\Desktop\python project\experienced-ai-backend\env\Lib\site-packages\django\core\handlers\exception.py", line 55, in inner
    response = get_response(request)
               ^^^^^^^^^^^^^^^^^^^^^
  File "C:\Users\yash.goyal\Desktop\python project\experienced-ai-backend\env\Lib\site-packages\django\core\handlers\base.py", line 197, in _get_response
    response = wrapped_callback(request, *callback_args, **callback_kwargs)
               ^^^^^^^^^^^^^^^^^^^^^^^^^^^^^^^^^^^^^^^^^^^^^^^^^^^^^^^^^^^^
  File "C:\Users\yash.goyal\Desktop\python project\experienced-ai-backend\env\Lib\site-packages\django\views\decorators\csrf.py", line 65, in _view_wrapper
    return view_func(request, *args, **kwargs)
           ^^^^^^^^^^^^^^^^^^^^^^^^^^^^^^^^^^^
  File "C:\Users\yash.goyal\Desktop\python project\experienced-ai-backend\env\Lib\site-packages\django\views\generic\base.py", line 104, in view
    return self.dispatch(request, *args, **kwargs)
           ^^^^^^^^^^^^^^^^^^^^^^^^^^^^^^^^^^^^^^^
  File "C:\Users\yash.goyal\Desktop\python project\experienced-ai-backend\env\Lib\site-packages\rest_framework\views.py", line 509, in dispatch
    response = self.handle_exception(exc)
               ^^^^^^^^^^^^^^^^^^^^^^^^^^
  File "C:\Users\yash.goyal\Desktop\python project\experienced-ai-backend\env\Lib\site-packages\rest_framework\views.py", line 469, in handle_exception
    self.raise_uncaught_exception(exc)
  File "C:\Users\yash.goyal\Desktop\python project\experienced-ai-backend\env\Lib\site-packages\rest_framework\views.py", line 480, in raise_uncaught_exception
    raise exc
  File "C:\Users\yash.goyal\Desktop\python project\experienced-ai-backend\env\Lib\site-packages\rest_framework\views.py", line 506, in dispatch
    response = handler(request, *args, **kwargs)
               ^^^^^^^^^^^^^^^^^^^^^^^^^^^^^^^^^
  File "C:\Users\yash.goyal\Desktop\python project\experienced-ai-backend\authentication\api\views.py", line 648, in post
    except Token.DoesNotExist:
           ^^^^^^^^^^^^^^^^^^
AttributeError: type object 'Token' has no attribute 'DoesNotExist'
ERROR 2024-03-04 18:15:59,012 log log.py 241 log_response 241692 Internal Server Error: /apiv1/logout/
Traceback (most recent call last):
  File "C:\Users\yash.goyal\Desktop\python project\experienced-ai-backend\env\Lib\site-packages\rest_framework\views.py", line 497, in dispatch
    self.initial(request, *args, **kwargs)
  File "C:\Users\yash.goyal\Desktop\python project\experienced-ai-backend\env\Lib\site-packages\rest_framework\views.py", line 406, in initial
    neg = self.perform_content_negotiation(request)
          ^^^^^^^^^^^^^^^^^^^^^^^^^^^^^^^^^^^^^^^^^
  File "C:\Users\yash.goyal\Desktop\python project\experienced-ai-backend\env\Lib\site-packages\rest_framework\views.py", line 310, in perform_content_negotiation
    return conneg.select_renderer(request, renderers, self.format_kwarg)
           ^^^^^^^^^^^^^^^^^^^^^^^^^^^^^^^^^^^^^^^^^^^^^^^^^^^^^^^^^^^^^
  File "C:\Users\yash.goyal\Desktop\python project\experienced-ai-backend\env\Lib\site-packages\rest_framework\negotiation.py", line 56, in select_renderer
    if media_type_matches(renderer.media_type, media_type):
                          ^^^^^^^^^^^^^^^^^^^
AttributeError: 'IsTokenValid' object has no attribute 'media_type'

During handling of the above exception, another exception occurred:

Traceback (most recent call last):
  File "C:\Users\yash.goyal\Desktop\python project\experienced-ai-backend\env\Lib\site-packages\rest_framework\request.py", line 416, in __getattr__
    return getattr(self._request, attr)
           ^^^^^^^^^^^^^^^^^^^^^^^^^^^^
AttributeError: 'WSGIRequest' object has no attribute 'accepted_renderer'

During handling of the above exception, another exception occurred:

Traceback (most recent call last):
  File "C:\Users\yash.goyal\Desktop\python project\experienced-ai-backend\env\Lib\site-packages\django\core\handlers\exception.py", line 55, in inner
    response = get_response(request)
               ^^^^^^^^^^^^^^^^^^^^^
  File "C:\Users\yash.goyal\Desktop\python project\experienced-ai-backend\env\Lib\site-packages\django\core\handlers\base.py", line 197, in _get_response
    response = wrapped_callback(request, *callback_args, **callback_kwargs)
               ^^^^^^^^^^^^^^^^^^^^^^^^^^^^^^^^^^^^^^^^^^^^^^^^^^^^^^^^^^^^
  File "C:\Users\yash.goyal\Desktop\python project\experienced-ai-backend\env\Lib\site-packages\django\views\decorators\csrf.py", line 65, in _view_wrapper
    return view_func(request, *args, **kwargs)
           ^^^^^^^^^^^^^^^^^^^^^^^^^^^^^^^^^^^
  File "C:\Users\yash.goyal\Desktop\python project\experienced-ai-backend\env\Lib\site-packages\django\views\generic\base.py", line 104, in view
    return self.dispatch(request, *args, **kwargs)
           ^^^^^^^^^^^^^^^^^^^^^^^^^^^^^^^^^^^^^^^
  File "C:\Users\yash.goyal\Desktop\python project\experienced-ai-backend\env\Lib\site-packages\rest_framework\views.py", line 509, in dispatch
    response = self.handle_exception(exc)
               ^^^^^^^^^^^^^^^^^^^^^^^^^^
  File "C:\Users\yash.goyal\Desktop\python project\experienced-ai-backend\env\Lib\site-packages\rest_framework\views.py", line 469, in handle_exception
    self.raise_uncaught_exception(exc)
  File "C:\Users\yash.goyal\Desktop\python project\experienced-ai-backend\env\Lib\site-packages\rest_framework\views.py", line 477, in raise_uncaught_exception
    renderer_format = getattr(request.accepted_renderer, 'format')
                              ^^^^^^^^^^^^^^^^^^^^^^^^^
  File "C:\Users\yash.goyal\Desktop\python project\experienced-ai-backend\env\Lib\site-packages\rest_framework\request.py", line 418, in __getattr__
    return self.__getattribute__(attr)
           ^^^^^^^^^^^^^^^^^^^^^^^^^^^
AttributeError: 'Request' object has no attribute 'accepted_renderer'
ERROR 2024-03-04 18:17:48,769 log log.py 241 log_response 242584 Internal Server Error: /apiv1/logout/
ERROR 2024-03-04 18:35:43,145 log log.py 241 log_response 242704 Internal Server Error: /apiv1/logout/
ERROR 2024-03-04 18:37:47,636 log log.py 241 log_response 230240 Internal Server Error: /apiv1/logout/
ERROR 2024-03-04 18:42:13,278 log log.py 241 log_response 245304 Internal Server Error: /apiv1/logout/
ERROR 2024-03-04 18:43:05,393 log log.py 241 log_response 245248 Internal Server Error: /apiv1/logout/
ERROR 2024-03-04 18:43:34,032 log log.py 241 log_response 245304 Internal Server Error: /apiv1/logout/
ERROR 2024-03-04 18:43:53,687 log log.py 241 log_response 244056 Internal Server Error: /apiv1/logout/
ERROR 2024-03-04 18:44:23,195 log log.py 241 log_response 243872 Internal Server Error: /apiv1/logout/
ERROR 2024-03-04 18:46:30,570 log log.py 241 log_response 243416 Internal Server Error: /apiv1/profile/
Traceback (most recent call last):
  File "C:\Users\yash.goyal\Desktop\python project\experienced-ai-backend\env\Lib\site-packages\django\core\handlers\exception.py", line 55, in inner
    response = get_response(request)
               ^^^^^^^^^^^^^^^^^^^^^
  File "C:\Users\yash.goyal\Desktop\python project\experienced-ai-backend\env\Lib\site-packages\django\core\handlers\base.py", line 197, in _get_response
    response = wrapped_callback(request, *callback_args, **callback_kwargs)
               ^^^^^^^^^^^^^^^^^^^^^^^^^^^^^^^^^^^^^^^^^^^^^^^^^^^^^^^^^^^^
  File "C:\Users\yash.goyal\Desktop\python project\experienced-ai-backend\env\Lib\site-packages\django\views\decorators\csrf.py", line 65, in _view_wrapper
    return view_func(request, *args, **kwargs)
           ^^^^^^^^^^^^^^^^^^^^^^^^^^^^^^^^^^^
  File "C:\Users\yash.goyal\Desktop\python project\experienced-ai-backend\env\Lib\site-packages\django\views\generic\base.py", line 104, in view
    return self.dispatch(request, *args, **kwargs)
           ^^^^^^^^^^^^^^^^^^^^^^^^^^^^^^^^^^^^^^^
  File "C:\Users\yash.goyal\Desktop\python project\experienced-ai-backend\env\Lib\site-packages\rest_framework\views.py", line 509, in dispatch
    response = self.handle_exception(exc)
               ^^^^^^^^^^^^^^^^^^^^^^^^^^
  File "C:\Users\yash.goyal\Desktop\python project\experienced-ai-backend\env\Lib\site-packages\rest_framework\views.py", line 469, in handle_exception
    self.raise_uncaught_exception(exc)
  File "C:\Users\yash.goyal\Desktop\python project\experienced-ai-backend\env\Lib\site-packages\rest_framework\views.py", line 480, in raise_uncaught_exception
    raise exc
  File "C:\Users\yash.goyal\Desktop\python project\experienced-ai-backend\env\Lib\site-packages\rest_framework\views.py", line 497, in dispatch
    self.initial(request, *args, **kwargs)
  File "C:\Users\yash.goyal\Desktop\python project\experienced-ai-backend\env\Lib\site-packages\rest_framework\views.py", line 415, in initial
    self.check_permissions(request)
  File "C:\Users\yash.goyal\Desktop\python project\experienced-ai-backend\env\Lib\site-packages\rest_framework\views.py", line 332, in check_permissions
    if not permission.has_permission(request, self):
           ^^^^^^^^^^^^^^^^^^^^^^^^^^^^^^^^^^^^^^^^
  File "C:\Users\yash.goyal\Desktop\python project\experienced-ai-backend\authentication\models.py", line 181, in has_permission
    token = request.auth.decode("utf-8")
            ^^^^^^^^^^^^^^^^^^^
AttributeError: 'AccessToken' object has no attribute 'decode'
ERROR 2024-03-04 18:48:16,957 log log.py 241 log_response 245416 Internal Server Error: /apiv1/profile/
Traceback (most recent call last):
  File "C:\Users\yash.goyal\Desktop\python project\experienced-ai-backend\env\Lib\site-packages\django\core\handlers\exception.py", line 55, in inner
    response = get_response(request)
               ^^^^^^^^^^^^^^^^^^^^^
  File "C:\Users\yash.goyal\Desktop\python project\experienced-ai-backend\env\Lib\site-packages\django\core\handlers\base.py", line 220, in _get_response
    response = response.render()
               ^^^^^^^^^^^^^^^^^
  File "C:\Users\yash.goyal\Desktop\python project\experienced-ai-backend\env\Lib\site-packages\django\template\response.py", line 114, in render
    self.content = self.rendered_content
                   ^^^^^^^^^^^^^^^^^^^^^
  File "C:\Users\yash.goyal\Desktop\python project\experienced-ai-backend\env\Lib\site-packages\rest_framework\response.py", line 70, in rendered_content
    ret = renderer.render(self.data, accepted_media_type, context)
          ^^^^^^^^^^^^^^^^^^^^^^^^^^^^^^^^^^^^^^^^^^^^^^^^^^^^^^^^
  File "C:\Users\yash.goyal\Desktop\python project\experienced-ai-backend\authentication\api\renderers.py", line 10, in render
    response_data['message'] = data['messages'][0]['message']
                               ~~~~^^^^^^^^^^^^
KeyError: 'messages'
ERROR 2024-03-04 18:50:14,693 log log.py 241 log_response 245472 Internal Server Error: /apiv1/profile/
Traceback (most recent call last):
  File "C:\Users\yash.goyal\Desktop\python project\experienced-ai-backend\env\Lib\site-packages\django\core\handlers\exception.py", line 55, in inner
    response = get_response(request)
               ^^^^^^^^^^^^^^^^^^^^^
  File "C:\Users\yash.goyal\Desktop\python project\experienced-ai-backend\env\Lib\site-packages\django\core\handlers\base.py", line 220, in _get_response
    response = response.render()
               ^^^^^^^^^^^^^^^^^
  File "C:\Users\yash.goyal\Desktop\python project\experienced-ai-backend\env\Lib\site-packages\django\template\response.py", line 114, in render
    self.content = self.rendered_content
                   ^^^^^^^^^^^^^^^^^^^^^
  File "C:\Users\yash.goyal\Desktop\python project\experienced-ai-backend\env\Lib\site-packages\rest_framework\response.py", line 70, in rendered_content
    ret = renderer.render(self.data, accepted_media_type, context)
          ^^^^^^^^^^^^^^^^^^^^^^^^^^^^^^^^^^^^^^^^^^^^^^^^^^^^^^^^
  File "C:\Users\yash.goyal\Desktop\python project\experienced-ai-backend\authentication\api\renderers.py", line 10, in render
    response_data['message'] = data['messages'][0]['message']
                               ~~~~^^^^^^^^^^^^
KeyError: 'messages'
ERROR 2024-03-04 18:52:18,426 log log.py 241 log_response 246704 Internal Server Error: /apiv1/profile/
Traceback (most recent call last):
  File "C:\Users\yash.goyal\Desktop\python project\experienced-ai-backend\env\Lib\site-packages\django\core\handlers\exception.py", line 55, in inner
    response = get_response(request)
               ^^^^^^^^^^^^^^^^^^^^^
  File "C:\Users\yash.goyal\Desktop\python project\experienced-ai-backend\env\Lib\site-packages\django\core\handlers\base.py", line 220, in _get_response
    response = response.render()
               ^^^^^^^^^^^^^^^^^
  File "C:\Users\yash.goyal\Desktop\python project\experienced-ai-backend\env\Lib\site-packages\django\template\response.py", line 114, in render
    self.content = self.rendered_content
                   ^^^^^^^^^^^^^^^^^^^^^
  File "C:\Users\yash.goyal\Desktop\python project\experienced-ai-backend\env\Lib\site-packages\rest_framework\response.py", line 70, in rendered_content
    ret = renderer.render(self.data, accepted_media_type, context)
          ^^^^^^^^^^^^^^^^^^^^^^^^^^^^^^^^^^^^^^^^^^^^^^^^^^^^^^^^
  File "C:\Users\yash.goyal\Desktop\python project\experienced-ai-backend\authentication\api\renderers.py", line 10, in render
    response_data['message'] = data['messages'][0]['message']
                               ~~~~^^^^^^^^^^^^
KeyError: 'messages'
ERROR 2024-03-04 18:52:55,839 log log.py 241 log_response 245992 Internal Server Error: /apiv1/profile/
Traceback (most recent call last):
  File "C:\Users\yash.goyal\Desktop\python project\experienced-ai-backend\env\Lib\site-packages\django\core\handlers\exception.py", line 55, in inner
    response = get_response(request)
               ^^^^^^^^^^^^^^^^^^^^^
  File "C:\Users\yash.goyal\Desktop\python project\experienced-ai-backend\env\Lib\site-packages\django\core\handlers\base.py", line 220, in _get_response
    response = response.render()
               ^^^^^^^^^^^^^^^^^
  File "C:\Users\yash.goyal\Desktop\python project\experienced-ai-backend\env\Lib\site-packages\django\template\response.py", line 114, in render
    self.content = self.rendered_content
                   ^^^^^^^^^^^^^^^^^^^^^
  File "C:\Users\yash.goyal\Desktop\python project\experienced-ai-backend\env\Lib\site-packages\rest_framework\response.py", line 70, in rendered_content
    ret = renderer.render(self.data, accepted_media_type, context)
          ^^^^^^^^^^^^^^^^^^^^^^^^^^^^^^^^^^^^^^^^^^^^^^^^^^^^^^^^
  File "C:\Users\yash.goyal\Desktop\python project\experienced-ai-backend\authentication\api\renderers.py", line 10, in render
    response_data['message'] = data['messages'][0]['message']
                               ~~~~^^^^^^^^^^^^
KeyError: 'messages'
ERROR 2024-03-04 18:53:32,056 log log.py 241 log_response 245852 Internal Server Error: /apiv1/profile/
Traceback (most recent call last):
  File "C:\Users\yash.goyal\Desktop\python project\experienced-ai-backend\env\Lib\site-packages\django\core\handlers\exception.py", line 55, in inner
    response = get_response(request)
               ^^^^^^^^^^^^^^^^^^^^^
  File "C:\Users\yash.goyal\Desktop\python project\experienced-ai-backend\env\Lib\site-packages\django\core\handlers\base.py", line 220, in _get_response
    response = response.render()
               ^^^^^^^^^^^^^^^^^
  File "C:\Users\yash.goyal\Desktop\python project\experienced-ai-backend\env\Lib\site-packages\django\template\response.py", line 114, in render
    self.content = self.rendered_content
                   ^^^^^^^^^^^^^^^^^^^^^
  File "C:\Users\yash.goyal\Desktop\python project\experienced-ai-backend\env\Lib\site-packages\rest_framework\response.py", line 70, in rendered_content
    ret = renderer.render(self.data, accepted_media_type, context)
          ^^^^^^^^^^^^^^^^^^^^^^^^^^^^^^^^^^^^^^^^^^^^^^^^^^^^^^^^
  File "C:\Users\yash.goyal\Desktop\python project\experienced-ai-backend\authentication\api\renderers.py", line 10, in render
    response_data['message'] = data['messages'][0]['message']
                               ~~~~^^^^^^^^^^^^
KeyError: 'messages'
